2025-07-29 13:30:22,935 INFO <module>(35) API DomingosAccess iniciada com sucesso.2025-07-29 13:39:55,058 INFO <module>(35) API DomingosAccess iniciada com sucesso.
2025-07-29 13:39:57,774 INFO cadastrar_usuario(75) Recebida tentativa de cadastro para: Wendel Samora, CPF: 111.222.333-44
2025-07-29 13:39:57,788 WARNING cadastrar_usuario(92) Validação local falhou para o CPF: 111.222.333-44 e Matrícula: 2024001.
2025-07-29 13:39:57,788 ERROR log_exception(875) Exception on / [POST]
Traceback (most recent call last):
  File "C:\Users\wendel.santos\Desktop\reconhecimento\env\lib\site-packages\flask\app.py", line 1511, in wsgi_app
    response = self.full_dispatch_request()
  File "C:\Users\wendel.santos\Desktop\reconhecimento\env\lib\site-packages\flask\app.py", line 919, in full_dispatch_request
    rv = self.handle_user_exception(e)
  File "C:\Users\wendel.santos\Desktop\reconhecimento\env\lib\site-packages\flask_cors\extension.py", line 176, in wrapped_function
    return cors_after_request(app.make_response(f(*args, **kwargs)))
  File "C:\Users\wendel.santos\Desktop\reconhecimento\env\lib\site-packages\flask\app.py", line 917, in full_dispatch_request
    rv = self.dispatch_request()
  File "C:\Users\wendel.santos\Desktop\reconhecimento\env\lib\site-packages\flask\app.py", line 902, in dispatch_request
    return self.ensure_sync(self.view_functions[rule.endpoint])(**view_args)  # type: ignore[no-any-return]
  File "c:\Users\wendel.santos\Desktop\reconhecimento\app.py", line 93, in cadastrar_usuario
    flash('Dados Invalidos, não autorizados ou inativos. Verifique suas informações e tente novamente.', 'danger')
  File "C:\Users\wendel.santos\Desktop\reconhecimento\env\lib\site-packages\flask\helpers.py", line 335, in flash
    session["_flashes"] = flashes
  File "C:\Users\wendel.santos\Desktop\reconhecimento\env\lib\site-packages\flask\sessions.py", line 104, in _fail
    raise RuntimeError(
RuntimeError: The session is unavailable because no secret key was set.  Set the secret_key on the application to something unique and secret.
2025-07-29 13:39:59,954 INFO cadastrar_usuario(75) Recebida tentativa de cadastro para: Wendel Samora, CPF: 111.222.333-44
2025-07-29 13:39:59,955 WARNING cadastrar_usuario(92) Validação local falhou para o CPF: 111.222.333-44 e Matrícula: 2024001.
2025-07-29 13:39:59,956 ERROR log_exception(875) Exception on / [POST]
Traceback (most recent call last):
  File "C:\Users\wendel.santos\Desktop\reconhecimento\env\lib\site-packages\flask\app.py", line 1511, in wsgi_app
    response = self.full_dispatch_request()
  File "C:\Users\wendel.santos\Desktop\reconhecimento\env\lib\site-packages\flask\app.py", line 919, in full_dispatch_request
    rv = self.handle_user_exception(e)
  File "C:\Users\wendel.santos\Desktop\reconhecimento\env\lib\site-packages\flask_cors\extension.py", line 176, in wrapped_function
    return cors_after_request(app.make_response(f(*args, **kwargs)))
  File "C:\Users\wendel.santos\Desktop\reconhecimento\env\lib\site-packages\flask\app.py", line 917, in full_dispatch_request
    rv = self.dispatch_request()
  File "C:\Users\wendel.santos\Desktop\reconhecimento\env\lib\site-packages\flask\app.py", line 902, in dispatch_request
    return self.ensure_sync(self.view_functions[rule.endpoint])(**view_args)  # type: ignore[no-any-return]
  File "c:\Users\wendel.santos\Desktop\reconhecimento\app.py", line 93, in cadastrar_usuario
    flash('Dados Invalidos, não autorizados ou inativos. Verifique suas informações e tente novamente.', 'danger')
  File "C:\Users\wendel.santos\Desktop\reconhecimento\env\lib\site-packages\flask\helpers.py", line 335, in flash
    session["_flashes"] = flashes
  File "C:\Users\wendel.santos\Desktop\reconhecimento\env\lib\site-packages\flask\sessions.py", line 104, in _fail
    raise RuntimeError(
RuntimeError: The session is unavailable because no secret key was set.  Set the secret_key on the application to something unique and secret.
2025-07-29 13:41:00,842 INFO cadastrar_usuario(75) Recebida tentativa de cadastro para: Wendel Samora, CPF: 111.222.333-44
2025-07-29 13:41:00,843 WARNING cadastrar_usuario(92) Validação local falhou para o CPF: 111.222.333-44 e Matrícula: 2024001.
2025-07-29 13:41:00,845 ERROR log_exception(875) Exception on / [POST]
Traceback (most recent call last):
  File "C:\Users\wendel.santos\Desktop\reconhecimento\env\lib\site-packages\flask\app.py", line 1511, in wsgi_app
    response = self.full_dispatch_request()
  File "C:\Users\wendel.santos\Desktop\reconhecimento\env\lib\site-packages\flask\app.py", line 919, in full_dispatch_request
    rv = self.handle_user_exception(e)
  File "C:\Users\wendel.santos\Desktop\reconhecimento\env\lib\site-packages\flask_cors\extension.py", line 176, in wrapped_function
    return cors_after_request(app.make_response(f(*args, **kwargs)))
  File "C:\Users\wendel.santos\Desktop\reconhecimento\env\lib\site-packages\flask\app.py", line 917, in full_dispatch_request
    rv = self.dispatch_request()
  File "C:\Users\wendel.santos\Desktop\reconhecimento\env\lib\site-packages\flask\app.py", line 902, in dispatch_request
    return self.ensure_sync(self.view_functions[rule.endpoint])(**view_args)  # type: ignore[no-any-return]
  File "c:\Users\wendel.santos\Desktop\reconhecimento\app.py", line 93, in cadastrar_usuario
    flash('Dados Invalidos, não autorizados ou inativos. Verifique suas informações e tente novamente.', 'danger')
  File "C:\Users\wendel.santos\Desktop\reconhecimento\env\lib\site-packages\flask\helpers.py", line 335, in flash
    session["_flashes"] = flashes
  File "C:\Users\wendel.santos\Desktop\reconhecimento\env\lib\site-packages\flask\sessions.py", line 104, in _fail
    raise RuntimeError(
RuntimeError: The session is unavailable because no secret key was set.  Set the secret_key on the application to something unique and secret.
2025-07-29 14:03:25,885 INFO <module>(36) API DomingosAccess iniciada com sucesso.
2025-07-29 14:04:01,509 INFO cadastrar_usuario(76) Recebida tentativa de cadastro para: Wendel Samora, CPF: 111.222.333-44
2025-07-29 14:04:01,510 WARNING cadastrar_usuario(93) Validação local falhou para o CPF: 111.222.333-44 e Matrícula: 2024001.
2025-07-29 15:35:50,871 INFO cadastrar_usuario(76) Recebida tentativa de cadastro para: Wendel Samora , CPF: 111.222.333-44
2025-07-29 15:35:50,875 WARNING cadastrar_usuario(93) Validação local falhou para o CPF: 111.222.333-44 e Matrícula: 2024001.
2025-07-29 15:35:59,126 INFO <module>(36) API DomingosAccess iniciada com sucesso.
2025-07-29 15:36:40,343 INFO cadastrar_usuario(76) Recebida tentativa de cadastro para: Wendel Samora , CPF: 111.222.333-44
2025-07-29 15:36:40,347 INFO cadastrar_usuario(98) Validação local bem-sucedida para o NOME: Wendel Samora
2025-07-29 15:37:00,367 ERROR log_exception(875) Exception on / [POST]
Traceback (most recent call last):
  File "C:\Users\wendel.santos\Desktop\reconhecimento\env\lib\site-packages\urllib3\connection.py", line 198, in _new_conn
    sock = connection.create_connection(
  File "C:\Users\wendel.santos\Desktop\reconhecimento\env\lib\site-packages\urllib3\util\connection.py", line 85, in create_connection
    raise err
  File "C:\Users\wendel.santos\Desktop\reconhecimento\env\lib\site-packages\urllib3\util\connection.py", line 73, in create_connection
    sock.connect(sa)
TimeoutError: timed out

The above exception was the direct cause of the following exception:

Traceback (most recent call last):
  File "C:\Users\wendel.santos\Desktop\reconhecimento\env\lib\site-packages\urllib3\connectionpool.py", line 787, in urlopen
    response = self._make_request(
  File "C:\Users\wendel.santos\Desktop\reconhecimento\env\lib\site-packages\urllib3\connectionpool.py", line 493, in _make_request
    conn.request(
  File "C:\Users\wendel.santos\Desktop\reconhecimento\env\lib\site-packages\urllib3\connection.py", line 445, in request
    self.endheaders()
  File "C:\Users\wendel.santos\AppData\Local\Programs\Python\Python310\lib\http\client.py", line 1271, in endheaders
    self._send_output(message_body, encode_chunked=encode_chunked)
  File "C:\Users\wendel.santos\AppData\Local\Programs\Python\Python310\lib\http\client.py", line 1031, in _send_output
    self.send(msg)
  File "C:\Users\wendel.santos\AppData\Local\Programs\Python\Python310\lib\http\client.py", line 969, in send
    self.connect()
  File "C:\Users\wendel.santos\Desktop\reconhecimento\env\lib\site-packages\urllib3\connection.py", line 276, in connect
    self.sock = self._new_conn()
  File "C:\Users\wendel.santos\Desktop\reconhecimento\env\lib\site-packages\urllib3\connection.py", line 207, in _new_conn
    raise ConnectTimeoutError(
urllib3.exceptions.ConnectTimeoutError: (<urllib3.connection.HTTPConnection object at 0x00000292A3196AD0>, 'Connection to 192.168.137.2 timed out. (connect timeout=20)')

The above exception was the direct cause of the following exception:

Traceback (most recent call last):
  File "C:\Users\wendel.santos\Desktop\reconhecimento\env\lib\site-packages\requests\adapters.py", line 667, in send
    resp = conn.urlopen(
  File "C:\Users\wendel.santos\Desktop\reconhecimento\env\lib\site-packages\urllib3\connectionpool.py", line 841, in urlopen
    retries = retries.increment(
  File "C:\Users\wendel.santos\Desktop\reconhecimento\env\lib\site-packages\urllib3\util\retry.py", line 519, in increment
    raise MaxRetryError(_pool, url, reason) from reason  # type: ignore[arg-type]
urllib3.exceptions.MaxRetryError: HTTPConnectionPool(host='192.168.137.2', port=80): Max retries exceeded with url: /cgi-bin/AccessUser.cgi?action=insertMulti (Caused by ConnectTimeoutError(<urllib3.connection.HTTPConnection object at 0x00000292A3196AD0>, 'Connection to 192.168.137.2 timed out. (connect timeout=20)'))

During handling of the above exception, another exception occurred:

Traceback (most recent call last):
  File "c:\Users\wendel.santos\Desktop\reconhecimento\Sistema\intelbras_api.py", line 58, in add_user_v2
    result = requests.get(
  File "C:\Users\wendel.santos\Desktop\reconhecimento\env\lib\site-packages\requests\api.py", line 73, in get
    return request("get", url, params=params, **kwargs)
  File "C:\Users\wendel.santos\Desktop\reconhecimento\env\lib\site-packages\requests\api.py", line 59, in request
    return session.request(method=method, url=url, **kwargs)
  File "C:\Users\wendel.santos\Desktop\reconhecimento\env\lib\site-packages\requests\sessions.py", line 589, in request
    resp = self.send(prep, **send_kwargs)
  File "C:\Users\wendel.santos\Desktop\reconhecimento\env\lib\site-packages\requests\sessions.py", line 703, in send
    r = adapter.send(request, **kwargs)
  File "C:\Users\wendel.santos\Desktop\reconhecimento\env\lib\site-packages\requests\adapters.py", line 688, in send
    raise ConnectTimeout(e, request=request)
requests.exceptions.ConnectTimeout: HTTPConnectionPool(host='192.168.137.2', port=80): Max retries exceeded with url: /cgi-bin/AccessUser.cgi?action=insertMulti (Caused by ConnectTimeoutError(<urllib3.connection.HTTPConnection object at 0x00000292A3196AD0>, 'Connection to 192.168.137.2 timed out. (connect timeout=20)'))

During handling of the above exception, another exception occurred:

Traceback (most recent call last):
  File "C:\Users\wendel.santos\Desktop\reconhecimento\env\lib\site-packages\flask\app.py", line 1511, in wsgi_app
    response = self.full_dispatch_request()
  File "C:\Users\wendel.santos\Desktop\reconhecimento\env\lib\site-packages\flask\app.py", line 919, in full_dispatch_request
    rv = self.handle_user_exception(e)
  File "C:\Users\wendel.santos\Desktop\reconhecimento\env\lib\site-packages\flask_cors\extension.py", line 176, in wrapped_function
    return cors_after_request(app.make_response(f(*args, **kwargs)))
  File "C:\Users\wendel.santos\Desktop\reconhecimento\env\lib\site-packages\flask\app.py", line 917, in full_dispatch_request
    rv = self.dispatch_request()
  File "C:\Users\wendel.santos\Desktop\reconhecimento\env\lib\site-packages\flask\app.py", line 902, in dispatch_request
    return self.ensure_sync(self.view_functions[rule.endpoint])(**view_args)  # type: ignore[no-any-return]
  File "c:\Users\wendel.santos\Desktop\reconhecimento\app.py", line 102, in cadastrar_usuario
    resultado = api.add_user_v2(
  File "c:\Users\wendel.santos\Desktop\reconhecimento\Sistema\intelbras_api.py", line 65, in add_user_v2
    raise Exception("ERROR - During Add New User using V2 command - ")
Exception: ERROR - During Add New User using V2 command - 
2025-07-29 15:38:41,377 INFO cadastrar_usuario(76) Recebida tentativa de cadastro para: Wendel Samora , CPF: 111.222.333-44
2025-07-29 15:38:41,377 INFO cadastrar_usuario(98) Validação local bem-sucedida para o NOME: Wendel Samora
2025-07-29 15:38:43,443 ERROR log_exception(875) Exception on / [POST]
Traceback (most recent call last):
  File "C:\Users\wendel.santos\Desktop\reconhecimento\env\lib\site-packages\urllib3\connection.py", line 198, in _new_conn
    sock = connection.create_connection(
  File "C:\Users\wendel.santos\Desktop\reconhecimento\env\lib\site-packages\urllib3\util\connection.py", line 85, in create_connection
    raise err
  File "C:\Users\wendel.santos\Desktop\reconhecimento\env\lib\site-packages\urllib3\util\connection.py", line 73, in create_connection
    sock.connect(sa)
ConnectionRefusedError: [WinError 10061] Nenhuma conexão pôde ser feita porque a máquina de destino as recusou ativamente

The above exception was the direct cause of the following exception:

Traceback (most recent call last):
  File "C:\Users\wendel.santos\Desktop\reconhecimento\env\lib\site-packages\urllib3\connectionpool.py", line 787, in urlopen
    response = self._make_request(
  File "C:\Users\wendel.santos\Desktop\reconhecimento\env\lib\site-packages\urllib3\connectionpool.py", line 493, in _make_request
    conn.request(
  File "C:\Users\wendel.santos\Desktop\reconhecimento\env\lib\site-packages\urllib3\connection.py", line 445, in request
    self.endheaders()
  File "C:\Users\wendel.santos\AppData\Local\Programs\Python\Python310\lib\http\client.py", line 1271, in endheaders
    self._send_output(message_body, encode_chunked=encode_chunked)
  File "C:\Users\wendel.santos\AppData\Local\Programs\Python\Python310\lib\http\client.py", line 1031, in _send_output
    self.send(msg)
  File "C:\Users\wendel.santos\AppData\Local\Programs\Python\Python310\lib\http\client.py", line 969, in send
    self.connect()
  File "C:\Users\wendel.santos\Desktop\reconhecimento\env\lib\site-packages\urllib3\connection.py", line 276, in connect
    self.sock = self._new_conn()
  File "C:\Users\wendel.santos\Desktop\reconhecimento\env\lib\site-packages\urllib3\connection.py", line 213, in _new_conn
    raise NewConnectionError(
urllib3.exceptions.NewConnectionError: <urllib3.connection.HTTPConnection object at 0x00000292A31961D0>: Failed to establish a new connection: [WinError 10061] Nenhuma conexão pôde ser feita porque a máquina de destino as recusou ativamente

The above exception was the direct cause of the following exception:

Traceback (most recent call last):
  File "C:\Users\wendel.santos\Desktop\reconhecimento\env\lib\site-packages\requests\adapters.py", line 667, in send
    resp = conn.urlopen(
  File "C:\Users\wendel.santos\Desktop\reconhecimento\env\lib\site-packages\urllib3\connectionpool.py", line 841, in urlopen
    retries = retries.increment(
  File "C:\Users\wendel.santos\Desktop\reconhecimento\env\lib\site-packages\urllib3\util\retry.py", line 519, in increment
    raise MaxRetryError(_pool, url, reason) from reason  # type: ignore[arg-type]
urllib3.exceptions.MaxRetryError: HTTPConnectionPool(host='192.168.137.2', port=80): Max retries exceeded with url: /cgi-bin/AccessUser.cgi?action=insertMulti (Caused by NewConnectionError('<urllib3.connection.HTTPConnection object at 0x00000292A31961D0>: Failed to establish a new connection: [WinError 10061] Nenhuma conexão pôde ser feita porque a máquina de destino as recusou ativamente'))

During handling of the above exception, another exception occurred:

Traceback (most recent call last):
  File "c:\Users\wendel.santos\Desktop\reconhecimento\Sistema\intelbras_api.py", line 58, in add_user_v2
    result = requests.get(
  File "C:\Users\wendel.santos\Desktop\reconhecimento\env\lib\site-packages\requests\api.py", line 73, in get
    return request("get", url, params=params, **kwargs)
  File "C:\Users\wendel.santos\Desktop\reconhecimento\env\lib\site-packages\requests\api.py", line 59, in request
    return session.request(method=method, url=url, **kwargs)
  File "C:\Users\wendel.santos\Desktop\reconhecimento\env\lib\site-packages\requests\sessions.py", line 589, in request
    resp = self.send(prep, **send_kwargs)
  File "C:\Users\wendel.santos\Desktop\reconhecimento\env\lib\site-packages\requests\sessions.py", line 703, in send
    r = adapter.send(request, **kwargs)
  File "C:\Users\wendel.santos\Desktop\reconhecimento\env\lib\site-packages\requests\adapters.py", line 700, in send
    raise ConnectionError(e, request=request)
requests.exceptions.ConnectionError: HTTPConnectionPool(host='192.168.137.2', port=80): Max retries exceeded with url: /cgi-bin/AccessUser.cgi?action=insertMulti (Caused by NewConnectionError('<urllib3.connection.HTTPConnection object at 0x00000292A31961D0>: Failed to establish a new connection: [WinError 10061] Nenhuma conexão pôde ser feita porque a máquina de destino as recusou ativamente'))

During handling of the above exception, another exception occurred:

Traceback (most recent call last):
  File "C:\Users\wendel.santos\Desktop\reconhecimento\env\lib\site-packages\flask\app.py", line 1511, in wsgi_app
    response = self.full_dispatch_request()
  File "C:\Users\wendel.santos\Desktop\reconhecimento\env\lib\site-packages\flask\app.py", line 919, in full_dispatch_request
    rv = self.handle_user_exception(e)
  File "C:\Users\wendel.santos\Desktop\reconhecimento\env\lib\site-packages\flask_cors\extension.py", line 176, in wrapped_function
    return cors_after_request(app.make_response(f(*args, **kwargs)))
  File "C:\Users\wendel.santos\Desktop\reconhecimento\env\lib\site-packages\flask\app.py", line 917, in full_dispatch_request
    rv = self.dispatch_request()
  File "C:\Users\wendel.santos\Desktop\reconhecimento\env\lib\site-packages\flask\app.py", line 902, in dispatch_request
    return self.ensure_sync(self.view_functions[rule.endpoint])(**view_args)  # type: ignore[no-any-return]
  File "c:\Users\wendel.santos\Desktop\reconhecimento\app.py", line 102, in cadastrar_usuario
    resultado = api.add_user_v2(
  File "c:\Users\wendel.santos\Desktop\reconhecimento\Sistema\intelbras_api.py", line 65, in add_user_v2
    raise Exception("ERROR - During Add New User using V2 command - ")
Exception: ERROR - During Add New User using V2 command - 
2025-07-29 15:38:46,233 INFO cadastrar_usuario(76) Recebida tentativa de cadastro para: Wendel Samora , CPF: 111.222.333-44
2025-07-29 15:38:46,235 INFO cadastrar_usuario(98) Validação local bem-sucedida para o NOME: Wendel Samora
2025-07-29 15:38:46,402 INFO cadastrar_usuario(111) Usuário 'Wendel Samora' (ID: 7) criado no dispositivo. Redirecionando para captura.
2025-07-29 15:41:42,322 INFO cadastrar_usuario(76) Recebida tentativa de cadastro para: Wemerson , CPF: 111.222.333-44
2025-07-29 15:41:42,324 WARNING cadastrar_usuario(93) Validação local falhou para o CPF: 111.222.333-44 e Matrícula: 18181818.
2025-07-29 15:42:19,116 INFO cadastrar_usuario(76) Recebida tentativa de cadastro para: Wemerson , CPF: 555.666.777-88
2025-07-29 15:42:19,118 INFO cadastrar_usuario(98) Validação local bem-sucedida para o NOME: Wemerson Thiago
2025-07-29 15:42:19,234 INFO cadastrar_usuario(111) Usuário 'Wemerson Thiago' (ID: 8) criado no dispositivo. Redirecionando para captura.
2025-07-29 16:07:52,938 INFO <module>(36) API DomingosAccess iniciada com sucesso.
2025-07-29 16:08:06,597 INFO cadastrar_usuario(76) Recebida tentativa de cadastro para: Wendel Samora , CPF: 111.222.333-44
2025-07-29 16:08:06,598 INFO cadastrar_usuario(98) Validação local bem-sucedida para o NOME: Wendel Samora
2025-07-29 16:08:06,675 INFO cadastrar_usuario(111) Usuário 'Wendel Samora' (ID: 9) criado no dispositivo. Redirecionando para captura.
2025-07-29 16:13:40,432 INFO cadastrar_usuario(76) Recebida tentativa de cadastro para: Wendel Samora , CPF: 111.222.333-44
2025-07-29 16:13:40,435 INFO cadastrar_usuario(98) Validação local bem-sucedida para o NOME: Wendel Samora
2025-07-29 16:13:40,538 INFO cadastrar_usuario(111) Usuário 'Wendel Samora' (ID: 10) criado no dispositivo. Redirecionando para captura.
2025-07-29 16:15:06,015 INFO <module>(36) API DomingosAccess iniciada com sucesso.
2025-07-29 16:18:26,132 INFO cadastrar_usuario(76) Recebida tentativa de cadastro para: Wendel Samora , CPF: 111.222.333-44
2025-07-29 16:18:26,134 INFO cadastrar_usuario(98) Validação local bem-sucedida para o NOME: Wendel Samora
2025-07-29 16:18:26,232 INFO cadastrar_usuario(111) Usuário 'Wendel Samora' (ID: 11) criado no dispositivo. Redirecionando para captura.
2025-07-29 16:19:02,861 INFO <module>(36) API DomingosAccess iniciada com sucesso.
2025-07-29 16:19:17,936 INFO <module>(36) API DomingosAccess iniciada com sucesso.
2025-07-29 16:19:27,457 INFO cadastrar_usuario(76) Recebida tentativa de cadastro para: Wendel Samora , CPF: 111.222.333-44
2025-07-29 16:19:27,459 INFO cadastrar_usuario(98) Validação local bem-sucedida para o NOME: Wendel Samora
2025-07-29 16:19:27,533 INFO cadastrar_usuario(111) Usuário 'Wendel Samora' (ID: 12) criado no dispositivo. Redirecionando para captura.
2025-07-29 16:19:52,922 INFO cadastrar_usuario(76) Recebida tentativa de cadastro para: Wendel Samora , CPF: 111.222.333-44
2025-07-29 16:19:52,923 INFO cadastrar_usuario(98) Validação local bem-sucedida para o NOME: Wendel Samora
2025-07-29 16:19:53,005 INFO cadastrar_usuario(111) Usuário 'Wendel Samora' (ID: 13) criado no dispositivo. Redirecionando para captura.
2025-07-30 10:31:24,151 INFO <module>(36) API DomingosAccess iniciada com sucesso.
2025-07-30 10:48:50,639 INFO cadastrar_usuario(76) Recebida tentativa de cadastro para: Wendel Samora , CPF: 111.222.333-44
2025-07-30 10:48:50,644 INFO cadastrar_usuario(98) Validação local bem-sucedida para o NOME: Wendel Samora
2025-07-30 10:48:50,822 INFO cadastrar_usuario(111) Usuário 'Wendel Samora' (ID: 14) criado no dispositivo. Redirecionando para captura.
